Workbook

Sheet 준비물
A1: 💝 신혼여행 준비물 체크리스트 💝 | G1: ✅ 진행률
F2: 👩 김보현 | G2: =COUNTIF(C4:C114,"☑") & " / " & 78 -> 1 / 78
B3: 항목 | C3: 👩 김보현 | D3: 👨 김채연 | E3: 비고 | F3: 👨 김채연 | G3: =COUNTIF(D4:D114,"☑") & " / " & 88 -> 1 / 88
A4: 🛂 필수 서류 (절대 빠지면 안 됨)
B5: 여권 (유효기간 6개월 이상) | C5: ☑ | D5: ☑ | E5: 출국 전 반드시 확인
B6: ESTA 승인서 출력본 | C6: ☐ | D6: ☐ | E6: 유효기간 2년
B7: 전자항공권 (e-Ticket) | C7: ☐ | D7: ☐ | E7: 스크린샷 + 출력본
B8: 호텔 바우처 (전 일정) | C8: ☐ | D8: ☐ | E8: 출력본 + 모바일
B9: 국제운전면허증 | C9: ☐ | D9: ☐ | E9: LA 렌터카 시 필수
B10: 여행자보험 증서 | C10: ☐ | D10: ☐
B11: 여권 사본 (분실 대비) | C11: ☐ | D11: ☐ | E11: 별도 보관
B12: 증명사진 2매 | C12: ☐ | D12: ☐ | E12: 여권 분실 시
A13: 💳 현금/카드
B14: 여권 지갑 | C14: ☐ | D14: ☐
B15: 해외결제 신용카드 2장 | C15: ☐ | D15: ☐ | E15: VISA/Master 분산
B16: 체크카드 (트래블카드) | C16: ☐ | D16: ☐ | E16: 트래블월렛/하나 등
B17: USD 현금 | C17: ☐ | D17: ☐ | E17: 팁/소액용 $1, $5 위주
B18: 원화 (공항용) | C18: ☐ | D18: ☐
A19: 📱 전자기기
B20: 휴대폰 | C20: ☐ | D20: ☐
B21: 휴대폰 충전기 + 케이블 | C21: ☐ | D21: ☐
B22: 보조배터리 (기내 반입만) | C22: ☐ | D22: ☐ | E22: 위탁수하물 금지
B23: 멀티 어댑터 (110V/A타입) | C23: ☐ | D23: ☐ | E23: 미국은 A타입 플러그
B24: 변압기 | C24: ☐ | D24: ☐ | E24: 고출력 기기용
B25: 노트북/태블릿 | C25: ☐ | D25: ☐ | E25: 필요 시
B26: 이어폰 | C26: ☐ | D26: ☐
B27: 필름카메라 + 필름 | C27: ☐ | D27: ☐ | E27: X-ray 검색대 주의
B28: 인스탁스 + 필름 | C28: ☐ | D28: ☐
B29: 셀카봉/짐벌 | C29: ☐ | D29: ☐
B30: 메모리카드/USB | C30: ☐ | D30: ☐
A31: 👗 의류 - 김보현
B32: 상의 6벌 | C32: ☐ | D32: — | E32: 13박이라 +2벌 추천
B33: 하의/원피스 5벌 | C33: ☐ | D33: —
B34: 속옷 7벌 | C34: ☐ | D34: —
B35: 양말/스타킹 7켤레 | C35: ☐ | D35: —
B36: 겉옷 1벌 (가디건/자켓) | C36: ☐ | D36: — | E36: 기내/냉방용
B37: 수영복 | C37: ☐ | D37: — | E37: 마이애미 비치
B38: 래시가드/비치웨어 | C38: ☐ | D38: —
B39: 잠옷 2벌 | C39: ☐ | D39: —
B40: 편한 신발 (운동화) | C40: ☐ | D40: — | E40: 많이 걸음
...

Sheet 사전예약
A1: 🎫 사전예약 체크리스트 (출국 전 완료)
A3: 도시 | B3: 카테고리 | C3: 예약 항목 | D3: 시간 | E3: 권장 예약 시점 | F3: 예약 사이트 | G3: 예상 비용 (KRW) | H3: ✅ 완료 | I3: 예약번호 / 메모
A4: 🗽 뉴욕 | B4: 투어 | C4: 맨하탄 원데이 워킹투어 (전망대, 크루즈 포함) - 6/3 09:00, 성인 2인 | D4: 8시간 | E4: ✅ 완료 | F4: 타미스 (tamice.com) | G4: =180*뉴욕!$B$4 -> 271800 | H4: ✅ 완료 | I4: 260429140912480-1
A5: 🗽 뉴욕 | B5: 미술관 | C5: 메트로폴리탄 미술관 도슨트 투어 (한국어, 2일차 6/2) | D5: 5시간 30분 | E5: ✅ 완료 | F5: 마이리얼트립 | G5: =50*뉴욕!$B$4 -> 75500 | H5: ✅ 완료 | I5: EXP-20260429-00015411
A6: 🗽 뉴욕 | B6: 전망대 | C6: SUMMIT One Vanderbilt 전망대 피크 (5일차 6/5 20:00, 성인 2인) | E6: ✅ 완료 | F6: 타미스 (tamice.com) | G6: =104*뉴욕!$B$4 -> 157040 | H6: ✅ 완료 | I6: 260429140912480-2
A7: 🗽 뉴욕 | B7: 공연 | C7: 해리포터 브로드웨이 공연 (4일차 19:00) | E7: 2주전 | F7: TodayTix / Telecharge / Lion King 공식 | G7: =180*뉴욕!$B$4 -> 271800
A8: 🗽 뉴욕 | B8: 다이닝 | C8: Keens Steakhouse (35번가, 6/5 17:30, 성인 2인) | D8: 2시간 | E8: ✅ 완료 | F8: Resy | G8: =300*뉴욕!$B$4 -> 453000 | H8: ✅ 완료 | I8: 6/5 (금) 17:30 예약 / 뉴욕 고전 스테이크 하우스 (1885~) / SUMMIT 20:00 이동 고려
A9: 🗽 뉴욕 | B9: 다이닝 | C9: Orsay 점심 예약 (메트 근처 프렌치 비스트로, 6/2 13:00 실내, 성인 2인) | D9: 1시간 | E9: ✅ 완료 | F9: Resy | G9: =120*뉴욕!$B$4 -> 181200 | H9: ✅ 완료 | I9: Resy 예약 완료 / 실내 1시 / 메트 도슨트 종료(12:40) 후 도보 이동
A10: 🗽 뉴욕 | B10: 스냅촬영 | C10: DUMBO 웨딩스냅 촬영 (2일차 17:00) | D10: 1시간 | E10: ✅ 완료 | F10: 리베뉴욕 | G10: =400*뉴욕!$B$4 -> 604000
A11: 🗽️ 뉴욕 | B11: 쇼핑 | C11: 우드버리 아울렛 왕복 셔틀버스 (5일차 6/5, 성인 2인) | D11: 1시간 (편도) | E11: ✅ 완료 | F11: 타미스 (tamice.com) | G11: =72*뉴욕!$B$4 -> 108720 | H11: ✅ 완료 | I11: 260518210826730 / Port Authority 4층 출발 / QR 1매로 왕복 2회 / 8~9시 출발 추천, 45분 전 도착 / 선착순 탑승
A12: 🗽️ 뉴욕 | B12: 다이닝 | C12: Carmine's 저녁 (브로드웨이 근처, 6/4 16:30, 성인 2인) | D12: 1시간 30분 | E12: ✅ 완료 | F12: OpenTable / carminesnyc.com | G12: =80*뉴욕!$B$4 -> 120800 | H12: ✅ 완료 | I12: 6/4 (목) 16:30 예약 / OpenTable / Standard seating / 해리포터 공연 19:00 전 저녁 / 패밀리 스타일 이탈리안
A13: 🏖️ 마이애미 | B13: 다이닝 | C13: Gianni's at the Former Versace Mansion (베르사체 맨션 런치, 2일차 6/7 12:30, 성인 2인) | D13: 2시간 | E13: ✅ 완료 | F13: OpenTable / villacasacasuarina.com | G13: =200*뉴욕!$B$4 -> 302000 | H13: ✅ 완료 | I13: 풀사이드 자리 요청 / 신혼여행 메모 / Standard seating
A14: 🏖️ 마이애미 | B14: 맛집 | C14: Joe's Stone Crab 예약 (웨이팅 길기로 유명, 3일차 6/8 19:00) | D14: 2시간 | E14: ⚠️ 5/25(월) 13:00 KST 예약 오픈 | F14: joesstonecrab.com | G14: =100*뉴욕!$B$4 -> 151000 | I14: ⚠️ 5/25(월) 13:00 KST 오픈 / 12:50부터 대기 → 13:00 정각 예약 / 플랜 B: 17:00 오픈런
A15: 🌴 LA | B15: 테마파크 | C15: 유니버설 스튜디오 + Express Pass 여부 결정 | E15: 1개월 전 | F15: universalstudioshollywood.com | G15: =240*뉴욕!$B$4 -> 362400
A16: 🌴 LA | B16: 스튜디오 투어 | C16: Warner Bros Studio Tour Plus | D16: 4시간 | E16: ✅ 완료 | F16: wbstudiotour.com | G16: =320*뉴욕!$B$4 -> 483200 | H16: ✅ | I16: 20260419-167513020
A17: 🌴 LA | B17: 미술관 | C17: The Broad (무료이지만 예약 필수) | E17: 2주 전 | F17: thebroad.org | G17: 0
A18: 🌴 LA | B18: 렌터카 | C18: LA 렌터카 예약 (풀커버 보험) | E18: 출국 2주 전 | F18: Hertz / Avis / Enterprise / 트립닷컴 | G18: =400*뉴욕!$B$4 -> 604000
A19: 🌴 LA | B19: 미술관 | C19: 게티 센터 주차 예약 (입장 무료, 주차 예약 필수) | D19: 5시간 | E19: 2주 전 | F19: getty.edu | G19: =25*뉴욕!$B$4 -> 37750 | I19: 6/12 (금) 오전 9시 예약 / 공식 사이트에서 시간대 지정
A20: 📄 공통 | B20: 보험/통신 | C20: 여행자보험 가입 | E20: ✅ 완료 | F20: 현대해상 다이렉트 (hi.co.kr) | G20: 50300 | H20: ✅ 완료 | I20: F-26DA-0123973 / 2026.06.01 21:00~06.14 15:00
A21: 📄 공통 | B21: 보험/통신 | C21: eSIM 또는 로밍 데이터 (Airalo / Holafly) | E21: 출국 1주 전 | F21: airalo.com / holafly.com | G21: =35*뉴욕!$B$4 -> 52850
A22: 📄 공통 | B22: 서류 | C22: ESTA 승인 (72시간 이내 신청 권장) | E22: ✅ 완료 | F22: esta.cbp.dhs.gov | G22: =21*뉴욕!$B$4 -> 31710 | H22: ✅ 완료
A23: 📄 공통 | B23: 서류 | C23: 국제운전면허증 발급 (LA 렌터카용) | E23: 출국 1~2주 전 | F23: 경찰서 / 운전면허시험장 | G23: =8*뉴욕!$B$4 -> 12080

Sheet 입국·서류
A1: 🛂 미국 입국 / 세관 / 서류 가이드
A3: ✏️ 입국심사 예상 질문 (영어 답변 준비)
A4: 질문 | B4: 추천 답변
A5: What's the purpose of your visit? | B5: Tourism. Honeymoon trip with my spouse.
A6: How long are you staying? | B6: 13 nights, 14 days. Returning to Korea on June 13.
A7: Where will you stay? | B7: New York: Millennium Hilton UN Plaza / Miami: Loews Miami Beach / LA: (호텔명 기입)
A8: What do you do for a living? | B8: (본인 직업 영문 기입)
A9: Are you traveling alone? | B9: No, I'm with my husband/wife. (동반자 같이 심사 잘 받기)
A10: Do you have a return ticket? | B10: Yes, here it is. (e-Ticket 보여주기)
A11: How much money do you have? | B11: About $XXX in cash and credit cards. (보통 $500 이상 권장)
A13: 🏨 호텔 주소 (입국심사용 영문)
A14: 도시 | B14: 호텔명 및 주소 (영문)
A15: 뉴욕 | B15: Millennium Hilton New York One UN Plaza, 1 United Nations Plaza, New York, NY 10017
A16: 마이애미 | B16: Loews Miami Beach Hotel, 1601 Collins Ave, Miami Beach, FL 33139 / TEL 1-305-604-1601
A17: LA | B17: Glendale, Los Angeles, CA (에어비앤비 체크인 후 정확한 주소 호스트에게 확인)
A19: 💰 면세 / 세관신고 (귀국시)
A20: 항목 | B20: 한도 / 주의사항
A21: 1인당 면세한도 | B21: $800 (초과 시 자진 신고 권장)
A22: 술 | B22: 1병 (1L 이하, $400 이하)
A23: 담배 | B23: 200개비리 (1보도)
A24: 향수 | B24: 60ml 이하
A25: 현금반출 | B25: $10,000 초과 시 신고 필수
A26: 면세주의 | B26: 동일 품목 도매서는 단 1개만 인정. 면세한도 초과 시 관세 + 부가세 폭탄
A28: ⚠️ 긴급연락처
A29: 주미국 한국대사관 (워싱턴DC) | B29: 1-202-939-5600
A30: 주뉴욕 총영사관 | B30: +1-646-674-6000 (주간) / +1-646-965-3639 (당직)
A31: 주로스앤젤레스 총영사관 | B31: 1-213-385-9300
A32: 영사콜센터 (24시간, 국내) | B32: 82-2-3210-404
A33: 미국 응급전화 | B33: 911 (경찰/소방/구급)
A34: 여권 분실 시 | B34: 1) 현지 경찰서 도난신고 → 2) 총영사관 여행증명서 발급 → 3) ESTA 재신청
A36: 💳 팁 가이드 (미국 필수 매너)
A37: 상황 | B37: 팁 옆의 금액
A38: 레스토랑 식사 | B38: 세전 금액의 18~22% (서비스 좋으면 20%+)
A39: 카페/패스트푸드 | B39: $1~2 또는 팁 항아리 (강제는 아님)
A40: 바 | B40: 음료 1잔당 $1~2
A41: 우버 / 택시 | B41: 15~20% (우버는 앱에서 설정)
A42: 호텔 벨맨 / 도어맨 | B42: 가방 1개당 $1~2
A43: 호텔 청소 (하우스키퍼) | B43: 하루에 $2~5 (머릿탁에 두면 가져감)
A44: 발레 주차 | B44: 키 받을/넘길 때 각 $2~5
A45: 투어 가이드 | B45: 투어 비용의 10~15%
...

Sheet 총예산
A1: 💰 신혼여행 총 예산 (2인 13박14일)
A3: 환율 (USD→KRW) | B3: 1480
A5: 카테고리 | B5: 항목 | C5: USD | D5: KRW | E5: 메모
A6: ✈️ 항공 | B6: ICN↔EWR/LAX 왕복 (에어프레미아 YP0131/YP0102, 2인) ✅ 결제완료 | C6: =1793400/B3 -> 1211.7568 | D6: =C6*$B$3 -> 1793400 | E6: ✅ KIM CHAEYEON / KIM BOHYEON
A7: ✈️ 항공 | B7: JFK→MIA 델타 DL1514 (CHAEYEON KIM 결제내역 확인) ✅ | C7: 214.88 | D7: =C7*$B$3 -> 318022.4 | E7: ✅ KIM CHAEYEON / KIM BOHYEON 2인 결제완료
A8: ✈️ 항공 | B8: FLL→LAX (제트블루 B62801, 2인) | C8: =563000/B3 -> 380.40541 | D8: =C8*$B$3 -> 563000 | E8: ✅ KIM CHAEYEON / KIM BOHYEON 2인 결제완료
A9: ✈️ 항공 | B9: (LAX→ICN 귀국은 6행에 포함됨) | C9: 0 | D9: =C9*$B$3 -> 0
A11: 🏨 호텔 | B11: 뉴욕 밀레니엄 힌튼 UN Plaza (5박) ✅ 결제완료 | C11: =2740070/B3 -> 1851.3986 | D11: =C11*$B$3 -> 2740070 | E11: ✅ 예약번호 2601131400EBBFES1
A12: 🏨 호텔 | B12: 마이애미 로우스 (3박) ✅ 결제완료 | C12: =2062698/B3 -> 1393.7149 | D12: =C12*$B$3 -> 2062698 | E12: ✅ 예약번호 HH2632689220
A13: 🏨 호텔 | B13: LA Glendale 에어비앤비 (4박) ✅ 결제완료 | C13: =1402628/B3 -> 947.72162 | D13: =C13*$B$3 -> 1402628 | E13: ✅ RCZ8RDRQQN · HMNYSSE8TT
A15: 🚗 교통 | B15: LA 렌터카 (4일, 보험포함) | C15: 400 | D15: =C15*$B$3 -> 592000
A16: 🚗 교통 | B16: 우버/택시 예산 (NY+MIA+공항 이동) | C16: 350 | D16: =C16*$B$3 -> 518000
A17: 🚗 교통 | B17: NY 지하철 OMNY (2인 5일) | C17: 80 | D17: =C17*$B$3 -> 118400
A18: ⛽ 주유·주차 (LA) | C18: 200 | D18: =C18*$B$3 -> 296000
A19: 🏨 호텔 현지결제 | B19: 뉴욕 Destination Fee (체크아웃 시 결제) | C19: =294730/B3 -> 199.14189 | D19: 294730
A20: 🏨 호텔 현지결제 | B20: 마이애미 Resort Fee (체크아웃 시 결제) | C20: =50.16*3 -> 150.48 | D20: =C20*B3 -> 222710.4
A21: 🏨 호텔 현지결제 | B21: 마이애미 조식 (선택, 로우스 조식 불포함) | C21: =42*2*3 -> 252 | D21: =C21*B3 -> 372960
A22: 🍽️ 식비 | B22: 조식 $20 + 점심 $40 + 저녁 $80 × 14일 × 2인 (팁 포함) | C22: =(20+40+80)*14*2*1.2 -> 4704 | D22: =C22*$B$3 -> 6961920
A23: 🍽️ 식비 | B23: 파인다이닝 2회 (NY+LA, 와인/팁 포함) | C23: 600 | D23: =C23*$B$3 -> 888000
A25: 🛍️ 쇼핑 | B25: 5번가 쇼핑 예산 | C25: 1000 | D25: =C25*$B$3 -> 1480000
A27: 📱 통신/보험 | B27: eSIM 2인 + 여행자보험 | C27: 135 | D27: =C27*$B$3 -> 199800
A29: 💵 예비·기타 (팁 추가, 한산용) | C29: 500 | D29: =C29*$B$3 -> 740000
A31: 🎯 총 합계 (USD) | C31: =SUM(C6:C30) -> 14570.499 | D31: =C31*$B$3 -> 21564339

Sheet 보험보장
A1: 📋 가입 정보 (현대해상 다이렉트 해외여행보험)
A2: 설계번호 | B2: F-26DA-0123973 | C2: 보험기간 | D2: 2026.06.01 21:00 ~ 2026.06.14 15:00
A3: 계약자/대표피보험자 | B3: 김채연 (총 2명) | C3: 총보험료 | D3: 50,300원 (일시납)
A4: 🛡️ 여행자보험 보장 내역 정리
A6: 구분 | B6: 보장 담보명 | C6: 보장 금액 | D6: 비고
A7: ✈️ 일정 문제 | B7: 지수형 출국항공기 지연보장 | C7: 100000 | D7: 정액보상, 2시간 이상 지연/결항, SET
A8: ✈️ 일정 문제 | B8: 항공기 및 수하물 지연비용보장 | C8: 300000 | D8: 실손보상, 출국항공기 지연·결항 제외, SET
A9: 🏥 상해/질병 | B9: 상해사망·후유장해 (해외여행중) | C9: 300000000 | D9: 본인만 (가족/동반인 사망보장 미가입)
A10: 🏥 상해/질병 | B10: 질병사망 및 80% 고도후유장해 | C10: 50000000 | D10: 본인만 가입
A11: 🏥 상해/질병 | B11: 해외여행 상해 - 해외의료실비 | C11: 50000000
A12: 🏥 상해/질병 | B12: 해외여행 질병 - 해외의료실비 | C12: 50000000
A13: 🏥 상해/질병 | B13: 해외여행 상해급여 - 국내의료실비 | C13: 50000000 | D13: 통원한도 20만원
A14: 🏥 상해/질병 | B14: 해외여행 질병급여 - 국내의료실비 | C14: 50000000 | D14: 통원한도 20만원
A15: 🏥 상해/질병 | B15: 해외여행 상해비급여 - 국내의료실비 | C15: 50000000 | D15: 통원한도 20만원
A16: 🏥 상해/질병 | B16: 해외여행 질병비급여 - 국내의료실비 | C16: 50000000 | D16: 통원한도 20만원
A17: 🏥 상해/질병 | B17: 해외여행 3대비급여 - 국내의료실비 | C17: 3500000
A18: 🏥 상해/질병 | B18: 해외여행 중 식중독 입원위험 | C18: 300000
A19: 🏥 상해/질병 | B19: 해외여행 중 특정전염병 발생 | C19: 300000
A20: 🏥 상해/질병 | B20: 해외여행 중 상해입원일당 | C20: 30000 | D20: 1일당
A21: 🆘 여행 중 사고 | B21: 중대사고 구조송환비용 등 | C21: 50000000 | D21: 7일 이상
A22: 🆘 여행 중 사고 | B22: 항공기납치 위로금 | C22: 1400000
A23: 🆘 여행 중 사고 | B23: 해외여행 중단사고 발생 추가비용 | C23: 300000
A24: 🆘 여행 중 사고 | B24: 여권분실 후 재발급비용 | C24: 200000
A25: 💼 물품 손상/도난 | B25: 휴대품 손해 (분실 제외) | C25: 2000000 | D25: 실손, 물품당 20만원 한도, 자기부담금 1만원
A26: 💼 물품 손상/도난 | B26: 해외여행 중 자택 도난손해 (가재) | C26: 3000000
A27: ⚖️ 배상책임 | B27: 일괄배상 (해외여행중) | C27: 50000000 | D27: 실손, 자기부담금 1만원
A28: ⚠️ 보험금 청구 시 주의사항
A29: 휴대품 도난 | B29: 현지 경찰서·지구대에 도난 접수 후 "도난증명서(Police Report)" 발급 필수
A30: 휴대품 보상 제외 | B30: 현금·여권·항공권·신용카드는 휴대품으로 인정 안 됨 (그 외 한도 물품당 20만)
A31: 분실은 보상 ✕ | B31: 휴대품·자택 도난만 보장, 단순 분실(잃어버림)은 보상 안 됨
A32: 자기부담금 | B32: 해외의료실비·휴대품·배상책임 각 1만원 / 국내 통원 급여 MAX(20%, 1~2만) · 비급여 MAX(30%, 3만)
A33: 의료비 청구 | B33: 현지 진료장·영문 진단서·영수증 보관 필수 (귀국 후 청구)
A34: 보상 불가 지역 | B34: 외교부 적색경보(철수권고)·흑색경보(여행금지)·특별여행주의보 지역 방문 시 보상 ✕
A35: 주거지 이동 외 | B35: 주거지 출발 전 · 도착 후 사고는 보상 ✕ (여행중 구간만 보장)
A36: ☎️ 사고접수 | B36: 콜센터 1588-5656 / www.hi.co.kr (24시간 접수)
A38: 📞 사고 발생 시 보상 절차 (5단계)
A39: 1. 접수 | B39: 콜센터 1588-5656 · 웹 · 팩스 · 이메일 이용 → 접수번호·담당자 문자 수신
A40: 2. 지급심사 | B40: 구비서류·사고내용 검토
A41: 3. 손해사정·사고조사 | B41: 3영업일 내 지급 불가 시 사유·예정일·가지급제도 안내 / 지급예정일 최대 30영업일
A42: 4. 진행결과 안내 | B42: 서면·문자·이메일 중 고객 선택 방식
...

Sheet 뉴욕
A1: ♥ 신혼여행 - 뉴욕 ♥
A2: 여행기간 | B2: 13박14일 (6/1 ~ 6/14) | D2: 항공편 (출국) | E2: 에어프레미아 YP0131 | 6/1 21:30 ICN → 22:30 EWR | 예약번호 A2938067 / D83SKT | G2: 비상연락처 | H2: 대사관: +1-202-939-5600
A3: 체류일수 | B3: 뉴욕 5일 (6/1~6/5) | 마이애미 3일 | LA 5일 | D3: 호텔 | E3: 밀레니엄 힐튼 뉴욕 유엔 원플라자 | G3: 체크인 | H3: 6/1 (월) 22:30 이후
A4: 환율 (1 USD =) | B4: 1510 | D4: 예약번호 | E4: 2601131400EBBFES1 | G4: 체크아웃 | H4: 6/6 (토) 오전
A6: 📅 일자 | B6: ⏰ 시간 | C6: 📍 장소 | D6: 🚕 이동 | E6: 📌 일정 | F6: 💵 USD | G6: 💰 KRW | H6: ✅ 체크 | J6: 📝 뉴욕 위시리스트
A7: 1일차 6월 1일 (월) 도착 | B7: 06:00 ~ 07:00 | G7: =IF(F7="","",F7*$B$4) | J7: 🎭 라이언킹 (뮤지컬)
B8: 07:00 ~ 08:00 | G8: =IF(F8="","",F8*$B$4) | J8: 🗽 자유의 여신상 페리
B9: 08:00 ~ 09:00 | G9: =IF(F9="","",F9*$B$4) | J9: 🏛️ 9/11 박물관 (약 2시간)
B10: 09:00 ~ 10:00 | G10: =IF(F10="","",F10*$B$4) | J10: 🌉 브루클린 브리지 / 덤보
B11: 10:00 ~ 11:00 | G11: =IF(F11="","",F11*$B$4) | J11: 🌳 센트럴파크
B12: 11:00 ~ 12:00 | G12: =IF(F12="","",F12*$B$4) | J12: 🛍️ 첼시마켓 → 하이라인 → 베슬
B13: 12:00 ~ 13:00 | G13: =IF(F13="","",F13*$B$4) | J13: 🎨 구겐하임 미술관
B14: 13:00 ~ 14:00 | G14: =IF(F14="","",F14*$B$4)
B15: 14:00 ~ 15:00 | G15: =IF(F15="","",F15*$B$4) | J15: 🍕 먹거리
B16: 15:00 ~ 16:00 | G16: =IF(F16="","",F16*$B$4) | J16: · 조스피자
B17: 16:00 ~ 17:00 | G17: =IF(F17="","",F17*$B$4) | J17: · 중국음식
B18: 17:00 ~ 18:00 | G18: =IF(F18="","",F18*$B$4) | J18: · 핫도그
B19: 18:00 ~ 19:00 | G19: =IF(F19="","",F19*$B$4) | J19: · 스테이크
B20: 19:00 ~ 20:00 | G20: =IF(F20="","",F20*$B$4) | J20: · 맥주
B21: 20:00 ~ 21:00 | G21: =IF(F21="","",F21*$B$4)
B22: 21:00 ~ 22:00 | G22: =IF(F22="","",F22*$B$4) | J22: 🎨 색상 범례
B23: 22:00 ~ 23:00 | E23: ✈️ 22:30 뉴어크(EWR) 도착 | G23: =IF(F23="","",F23*$B$4) | J23: 🍽️ 식사
B24: 23:00 ~ 00:00 | C24: 밀레니엄 힐튼 | D24: 우버/택시 (~30분) | E24: 🚖 우버 → 호텔 체크인 | G24: =IF(F24="","",F24*$B$4) | J24: 🎫 투어/예약
B25: 일일 합계 | F25: =SUM(F7:F24) -> 0 | G25: =F25*$B$4 -> 0 | J25: 🎨 문화/액티비티
A27: 2일차 6월 2일 (화) | B27: 06:00 ~ 07:00 | C27: 호텔 | D27: 🏨 기상 | E27: 06:30 ⏰ 기상 / 06:30~07:00 🚿 샤워 시작 | G27: =IF(F27="","",F27*$B$4) | J27: 🛍️ 우드버리 아울렛 (5일차)
B28: 07:00 ~ 08:00 | C28: 호텔 | D28: 🚿 준비 | E28: 07:00~07:30 메이크 / 옷 준비 | G28: =IF(F28="","",F28*$B$4) | J28: · Coach (코치) — 본진, 가격 차이 큼
B29: 08:00 ~ 09:00 | C29: Ralph's Coffee | D29: ☕ 아침 | E29: 07:30~08:15 ☕ Ralph's Coffee (메트 근처 도보 15분) | G29: =IF(F29="","",F29*$B$4) | J29: · Tory Burch (토리버치) — 플랫슈즈/가방
B30: 09:00 ~ 10:00 | C30: → Metropolitan | D30: 🚇 4/5/6 → 86 St | E30: 08:15~09:00 🚇 메트로폴리탄 이동 (6호선 86 St → 도보) | G30: =IF(F30="","",F30*$B$4) | J30: · Polo Ralph Lauren — 셔츠/니트
B31: 10:00 ~ 11:00 | C31: Metropolitan Museum | D31: 🚶 도보 | E31: 09:30 도착 → 10:00 입장 | G31: =IF(F31="","",F31*$B$4) | J31: · Kate Spade — 가방/지갑
B32: 11:00 ~ 12:00 | C32: Metropolitan Museum | E32: 10:10~11:00 🎨 메트 도슨트 투어 시작 | G32: =IF(F32="","",F32*$B$4) | J32: · Michael Kors — 가방
B33: 12:00 ~ 13:00 | C33: Café Sabarsky / Sant Ambroeus / Orsay | D33: 🍽️ 점심 | E33: 11:00~12:00 도슨트 계속 | G33: =IF(F33="","",F33*$B$4) | J33: · Nike / Adidas — 운동화
B34: 13:00 ~ 14:00 | C34: 메트 자유관람 | D34: 🎨 자유관람 | E34: 12:00~12:40 도슨트 마무리 / 12:40~13:00 점심 이동 | G34: =IF(F34="","",F34*$B$4) | J34: · Levi's — 청바지
B35: 14:00 ~ 15:00 | C35: Orsay | D35: 🚶 센트럴파크 산책 | E35: 13:00~14:00 🍰 Orsay (메트 근처 프렌치 비스트로, 실내 1시 예약) | G35: =IF(F35="","",F35*$B$4) | J35: · Tumi / Samsonite — 캐리어 (귀국 짐용)
B36: 15:00 ~ 16:00 | C36: → DUMBO | D36: 🚖 우버 (약 30~40분) | E36: 14:00~15:00 🎨 메트 자유관람 | G36: =IF(F36="","",F36*$B$4) | J36: · The North Face / Columbia — 아우터
B37: 16:00 ~ 17:00 | C37: → DUMBO | D37: 🚖 우버 | E37: 15:00~16:00 🌳 센트럴파크 산책 (선택) | G37: =IF(F37="","",F37*$B$4) | J37: · Calvin Klein / Tommy Hilfiger — 기본템
B38: 17:00 ~ 18:00 | C38: DUMBO | E38: 16:00~17:00 🚖 우버 → 호텔 (의상/메이크) → DUMBO | G38: =IF(F38="","",F38*$B$4) | J38: · Le Creuset — 주방용품 (무게 주의)
B39: 18:00 ~ 19:00 | C39: Juliana's | D39: 🚶 도보 | E39: 17:00~18:00 📸 웨딩스납 촬영 | G39: =IF(F39="","",F39*$B$4) | J39: 💡 입장시 VIP 쿠폰북 수령 (안내센터)
B40: 19:00 ~ 20:00 | C40: Randolph Beer DUMBO | D40: 🚶 도보 (~5분) | E40: 18:00~19:00 🍕 Juliana's 피자 | G40: =IF(F40="","",F40*$B$4) | J40: 🚌 타미스 왕복버스 $36 (성인), Port Authority 4층 출발
B41: 20:00 ~ 21:00 | C41: 호텔 | D41: 🚖 우버 | E41: 19:00~20:00 🍺 Randolph Beer DUMBO | G41: =IF(F41="","",F41*$B$4) | J41: ⏰ 8~9시 출발 추천, 45분 전 터미널 도착
B42: 21:00 ~ 22:00 | E42: 20:00~21:00 Randolph (계속) → 21:00 🚖 호텔 복귀 | G42: =IF(F42="","",F42*$B$4) | J42: 📱 QR 1매로 왕복 2회 (중복스캔 주의)
...

Sheet 마이애미
A1: ♥ 신혼여행 - 마이애미 ♥
A2: 여행기간 | B2: 13박14일 (6/1 ~ 6/14) | D2: 항공편 | E2: 입국: 델타 DL1514 | 6/6 11:05 JFK → 14:19 MIA | 2인 결제완료 (티켓 #0062409793257/258) | G2: 비상연락처 | H2: 대사관: +1-202-939-5600
A3: 체류일수 | B3: 마이애미 3일 (6/6~6/8) | D3: 호텔 | E3: 로우스 마이애미 비치 호텔 | G3: 체크인 | H3: 6/6 (토) 오후
A4: 환율 (1 USD =) | B4: =뉴욕!B4 -> 1510 | D4: 예약번호 | E4: HH2632689220 (하나투어) / 로우스 컨펌 #2062698 | G4: 체크아웃 | H4: 6/8 (월) 오전
A6: 📅 일자 | B6: ⏰ 시간 | C6: 📍 장소 | D6: 🚕 이동 | E6: 📌 일정 | F6: 💵 USD | G6: 💰 KRW | H6: ✅ 체크 | J6: 📝 마이애미 위시리스트
A7: 1일차 6월 6일 (토) | B7: 06:00 ~ 07:00 | G7: =IF(F7="","",F7*$B$4) | J7: 🏊 풀파티
B8: 07:00 ~ 08:00 | G8: =IF(F8="","",F8*$B$4) | J8: 🪩 클럽
B9: 08:00 ~ 09:00 | G9: =IF(F9="","",F9*$B$4) | J9: 🦀 조스 스톤크랩
B10: 09:00 ~ 10:00 | G10: =IF(F10="","",F10*$B$4) | J10: 🛍️ 아울렛
B11: 10:00 ~ 11:00 | G11: =IF(F11="","",F11*$B$4) | J11: 🏖️ 해변
B12: 11:00 ~ 12:00 | E12: 11:05 ✈️ JFK 출발 (델타 DL1514) | G12: =IF(F12="","",F12*$B$4) | J12: 🥪 쿠바 샌드위치
B13: 12:00 ~ 13:00 | E13: 비행 중 (3h 14m) | G13: =IF(F13="","",F13*$B$4) | J13: 🏛️ 베르사체 맨션
B14: 13:00 ~ 14:00 | E14: 비행 중 | G14: =IF(F14="","",F14*$B$4) | J14: 🌴 리틀 하바나
B15: 14:00 ~ 15:00 | C15: MIA 공항 | D15: ✈️ 항공 | E15: 14:19 🛬 MIA 도착 | G15: =IF(F15="","",F15*$B$4) | J15: 🍕 볼보 피자
B16: 15:00 ~ 16:00 | G16: =IF(F16="","",F16*$B$4)
B17: 16:00 ~ 17:00 | C17: 로우스 마이애미 | D17: 🚕 우버 (공항→호텔) | E17: 15:30 🚖 우버 → 호텔 체크인 (로우스 마이애미 비치) | G17: =IF(F17="","",F17*$B$4)
B18: 17:00 ~ 18:00 | C18: Wynwood Walls | D18: 🚕 우버 (~15분) | E18: 17:00 🎨 윈우드 월스 (벽화 거리, 추천) | G18: =IF(F18="","",F18*$B$4)
B19: 18:00 ~ 19:00 | C19: Lincoln Road | D19: 🚶 도보 (호텔 근처) | E19: 18:00 🚶 링컨로드 산책 | G19: =IF(F19="","",F19*$B$4)
B20: 19:00 ~ 20:00 | C20: Trader Joe's | D20: 🚶 도보 | E20: 19:00 🛒 트레이더조 | G20: =IF(F20="","",F20*$B$4)
B21: 20:00 ~ 21:00 | D21: 🚶 도보 | E21: 20:00 🍕 Havana1957 | G21: =IF(F21="","",F21*$B$4)
B22: 21:00 ~ 22:00 | G22: =IF(F22="","",F22*$B$4)
B23: 22:00 ~ 23:00 | G23: =IF(F23="","",F23*$B$4)
B24: 23:00 ~ 00:00 | G24: =IF(F24="","",F24*$B$4)
B25: 일일 합계 | F25: =SUM(F7:F24) -> 0 | G25: =F25*$B$4 -> 0
A27: 2일차 6월 7일 (일) | B27: 06:00 ~ 07:00 | G27: =IF(F27="","",F27*$B$4)
B28: 07:00 ~ 08:00 | C28: 호텔 | D28: 🏨 기상 | E28: 07:30 ⏰ 기상 / 07:30~08:00 🚿 샤워 시작 | G28: =IF(F28="","",F28*$B$4)
B29: 08:00 ~ 09:00 | C29: 호텔 | D29: 😴 | E29: 08:00~08:30 메이크 / 옷 준비 / 08:30~09:00 우버 호출 준비 | G29: =IF(F29="","",F29*$B$4)
B30: 09:00 ~ 10:00 | C30: → Little Havana | D30: 🚕 우버 (~25분) | E30: 09:00~09:30 🚕 우버 출발 → 09:30 Versailles 도착 | G30: =IF(F30="","",F30*$B$4)
B31: 10:00 ~ 11:00 | C31: Versailles | D31: 🥪 브러치 | E31: 10:00~11:00 🥪 Versailles 쿠바 샌드위치 + 카페 콘 레체 브러치 | G31: =IF(F31="","",F31*$B$4)
B32: 11:00 ~ 12:00 | C32: Calle Ocho | D32: 🚶 도보 | E32: 11:00~12:00 칼레 오초 산책 / 시가 가게 | G32: =IF(F32="","",F32*$B$4)
B33: 12:00 ~ 13:00 | C33: → Versace Mansion | D33: 🚕 우버 (~25분) | E33: 12:00~12:30 🚕 우버 → 베르사체 맨션 / 12:30~13:00 런치 시작 | G33: =IF(F33="","",F33*$B$4)
B34: 13:00 ~ 14:00 | C34: Versace Mansion | D34: 🍽️ 런치 | E34: 13:00~14:00 🥂 Villa Casa Casuarina 런치 | G34: =IF(F34="","",F34*$B$4)
B35: 14:00 ~ 15:00 | C35: 오션드라이브 | D35: 🚶 도보 | E35: 14:00~14:30 런치 마무리 / 14:30~15:00 오션드라이브 산책 | G35: =IF(F35="","",F35*$B$4)
B36: 15:00 ~ 16:00 | C36: 호텔 풀 | D36: 🏊 | E36: 15:00~16:00 🏖️ 아르데코 지구 산책 | G36: =IF(F36="","",F36*$B$4)
B37: 16:00 ~ 17:00 | C37: 호텔 풀 | D37: 🏊 | E37: 16:00~17:00 🏊 호텔 복귀 / 수영장 풀파티 | G37: =IF(F37="","",F37*$B$4)
B38: 17:00 ~ 18:00 | C38: 호텔 | D38: 🏨 | E38: 17:00~17:30 풀 / 17:30~18:00 호텔 휴식 | G38: =IF(F38="","",F38*$B$4)
B39: 18:00 ~ 19:00 | C39: 링컨로드 | D39: 🚶 도보 | E39: 18:00~18:30 저녁 준비 / 18:30~19:00 링컴로드 산책 | G39: =IF(F39="","",F39*$B$4)
... B41: 20:00 ~ 21:00 | C41: 링컨로드 | D41: 🍸 바 | E41: 20:00~21:00 저녁 계속 | G41: =IF(F41="","",F41*$B$4)
B42: 21:00 ~ 22:00 | E42: 21:00~22:00 🍸 Sweet Liberty | G42: =IF(F42="","",F42*$B$4)
B43: 22:00 ~ 23:00 | E43: 22:00~22:30 Sweet Liberty 마무리 | G43: =IF(F43="","",F43*$B$4)
...

Sheet LA
A1: ♥ 신혼여행 - LA ♥
A2: 여행기간 | B2: 13박14일 (6/1 ~ 6/14) | D2: 항공편 | E2: 입국: 제트블루 B62801 | 6/9 09:20 FLL → 12:04 LAX | PNR KXRXAE (트립닷컴) 귀국: 에어프레미아 YP0102 | 6/13 10:50 LAX → 6/14 15:45 ICN | 예약번호 A2938067 | G2: 비상연락처 | H2: 대사관: +1-202-939-5600
A3: 체류일수 | B3: LA 5일 (6/9~6/13) | 6/13 오전 출국 | D3: 호텔 | E3: Glendale 에어비앤비 (호스트: Yulia Khundyukova) | G3: 체크인 | H3: 6/9 (월) 12:00 이후
A4: 환율 (1 USD =) | B4: =뉴욕!B4 -> 1510 | D4: 예약번호 | E4: RCZ8RDRQQN / HMNYSSE8TT | G4: 체크아웃 | H4: 6/13 (토) 오전
A6: 📅 일자 | B6: ⏰ 시간 | C6: 📍 장소 | D6: 🚕 이동 | E6: 📌 일정 | F6: 💵 USD | G6: 💰 KRW | H6: ✅ 체크 | J6: 📝 LA 위시리스트
A7: 1일차 6월 9일 (화) 도착 | B7: 06:00 ~ 07:00 | C7: FLL 공항 | D7: 🚖 우버 | E7: 06:00 🚖 호텔 → FLL 공항 (우버, ~50분) | G7: =IF(F7="","",F7*$B$4) | J7: 🏖️ 산타모니카 비치
B8: 07:00 ~ 08:00 | C8: FLL T3 | D8: ✈️ 체크인 | E8: 07:00 ✅ 체크인 / 보안검색 | G8: =IF(F8="","",F8*$B$4) | J8: 🎢 유니버설 스튜디오
B9: 08:00 ~ 09:00 | G9: =IF(F9="","",F9*$B$4) | J9: 🎬 워너브라더스 스튜디오 투어
B10: 09:00 ~ 10:00 | E10: 09:20 ✈️ FLL 출발 (제트블루) | G10: =IF(F10="","",F10*$B$4) | J10: 🌃 그리피스 천문대
B11: 10:00 ~ 11:00 | E11: 비행 중 | G11: =IF(F11="","",F11*$B$4) | J11: 🎨 게티 미술관
B12: 11:00 ~ 12:00 | E12: 비행 중 | G12: =IF(F12="","",F12*$B$4) | J12: 🌴 베니스 비치
B13: 12:00 ~ 13:00 | C13: LAX T1 | D13: 🛬 도착 | E13: 12:04 🛬 LAX 도착 (T1) / 짐 + 입국 절차 | G13: =IF(F13="","",F13*$B$4) | J13: ⭐ 할리우드
B14: 13:00 ~ 14:00 | C14: LAX | D14: 🚗 렌터카 픽업 | E14: 12:30~13:15 🚗 렌터카 픽업 / 공항 빠져나오기 | G14: =IF(F14="","",F14*$B$4)
B15: 14:00 ~ 15:00 | C15: → In-N-Out | D15: 🚗 이동 | E15: 13:15~13:30 🚗 In-N-Out 이동 (LAX 근처) | G15: =IF(F15="","",F15*$B$4) | J15: 🚗 렌터카 메모
B16: 15:00 ~ 16:00 | C16: In-N-Out | D16: 🍔 점심 | E16: 13:30~14:15 🍔 In-N-Out (여유롭게 첫 미국 감성) | G16: =IF(F16="","",F16*$B$4) | J16: · 픽업: LAX (6/9 12:04 이후)
B17: 16:00 ~ 17:00 | C17: Trader Joe's | D17: 🛒 장보기 | E17: 14:30~15:15 🛒 Trader Joe's (물/간식/와인 미리 확보) | G17: =IF(F17="","",F17*$B$4) | J17: · 반납: LAX (6/13 오전)
B18: 17:00 ~ 18:00 | C18: 호텔 (Glendale) | D18: 🏨 체크인 | E18: 15:30~17:00 🏨 호텔 체크인 + 샤워 + 휴식 (체력 회복) | G18: =IF(F18="","",F18*$B$4) | J18: · 국제운전면허증 + 한국면허증
B19: 18:00 ~ 19:00 | C19: → Griffith | D19: 🚗 이동 (~30분) | E19: 17:15 🚗 호텔 → 그리피스 천문대 출발 | G19: =IF(F19="","",F19*$B$4) | J19: · 신용카드 (보증금)
B20: 19:00 ~ 20:00 | C20: Griffith Observatory | D20: 🌅 sunset | E20: 18:00~19:30 🌅 그리피스 천문대 (sunset + 매직아워) | G20: =IF(F20="","",F20*$B$4) | J20: · 풀커버 보험 권장
B21: 20:00 ~ 21:00 | C21: Griffith Observatory | D21: 🌃 야경 | E21: 19:30~20:30 🌃 LA 야경 감상 | G21: =IF(F21="","",F21*$B$4) | J21: · 주유소: 셀프 (Chevron/Shell)
B22: 21:00 ~ 22:00 | C22: Hollywood Blvd | D22: 🚗 이동 / ⭐ 산책 | E22: 20:45~21:30 ⭐ 할리우드 (TCL, Dolby, Walk of Fame 핵심만) | G22: =IF(F22="","",F22*$B$4) | J22: · 게티/유니버설 주차비 별도
B23: 22:00 ~ 23:00 | C23: → 호텔 | D23: 🚗 복귀 | E23: 21:30~22:00 🚗 호텔 복귀 | G23: =IF(F23="","",F23*$B$4)
B24: 23:00 ~ 00:00 | C24: 호텔 | D24: 🍷 휴식 | E24: 22:00 🍷 와인 + Trader Joe's 간식 / 휴식 | G24: =IF(F24="","",F24*$B$4) | J24: 🎬 워너브라더스 예약
B25: 일일 합계 | F25: =SUM(F7:F24) -> 0 | G25: =F25*$B$4 -> 0 | J25: · 일시: 6/11 (목) 09:00
J26: · 티켓: Studio Tour Plus × 2
A27: 2일차 6월 10일 (수) | B27: 06:00 ~ 07:00 | C27: 호텔 | D27: 🏨 기상 | G27: =IF(F27="","",F27*$B$4) | J27: · 금액: $320 (AMEX 결제완료)
B28: 07:00 ~ 08:00 | C28: 호텔 | D28: ☕ 준비 / 조식 | E28: 07:00 ⏰ 기상 / 07:00~08:00 🚿 채비 + 간단 조식 | G28: =IF(F28="","",F28*$B$4) | J28: · 예약번호: 20260419-167513020
B29: 08:00 ~ 09:00 | C29: → Universal | D29: 🚗 렌터카 | E29: 08:00~09:00 🚗 호텔 → 유니버설 (아침 러시 30~45분, 여유) | G29: =IF(F29="","",F29*$B$4)
B30: 09:00 ~ 10:00 | C30: Universal Studios | D30: 🚗 호텔 → 유니버설 (~25분) | E30: 09:00~10:00 🎢 유니버설 입장 / 첨 어트랙션 | G30: =IF(F30="","",F30*$B$4) | L30: 🛒 한국인 인기 쇼핑 리스트
B31: 10:00 ~ 11:00 | E31: 10:00~11:00 🎢 유니버설 스튜디오 | G31: =IF(F31="","",F31*$B$4) | L31: [Costco 코스트코]
B32: 11:00 ~ 12:00 | E32: 11:00~12:00 🎢 유니버설 스튜디오 | G32: =IF(F32="","",F32*$B$4) | L32: · Kirkland 영양제 (오메가3, 비타민)
B33: 12:00 ~ 13:00 | E33: 12:00~13:00 🍔 유니버설 / 점심 | G33: =IF(F33="","",F33*$B$4) | L33: · 맥넘스 견과류 (아몬드/피칸)
B34: 13:00 ~ 14:00 | E34: 13:00~14:00 🎢 유니버설 스튜디오 | G34: =IF(F34="","",F34*$B$4) | L34: · Kirkland 올리브오일
B35: 14:00 ~ 15:00 | D35: 🚗 유니버설 인근 | E35: 14:00~15:00 🎢 유니버설 스튜디오 | G35: =IF(F35="","",F35*$B$4) | L35: · 프로틴파우더/손말테키라
B36: 15:00 ~ 16:00 | E36: 15:00~16:00 🎢 유니버설 스튜디오 | G36: =IF(F36="","",F36*$B$4) | L36: · 메이플시럽, 렉섬 꿀
B37: 16:00 ~ 17:00 | C37: Universal Studios | D37: 🎢 마무리 | E37: 16:00~17:00 🎢 유니버설 마무리 | G37: =IF(F37="","",F37*$B$4) | L37: · 아웃드래그 서프
B38: 17:00 ~ 18:00 | C38: Walmart Garden Center | D38: 🌿 가든센터 | E38: 17:00~18:00 🌿 월마트 가든센터 | G38: =IF(F38="","",F38*$B$4) | L38: [Walmart 월마트]
B39: 18:00 ~ 19:00 | C39: Costco (Burbank) | D39: 🛒 구경 + 저녁 | E39: 18:00~19:30 🛒 코스트코 (구경 + 🍕 푸드코트 저녁) | G39: =IF(F39="","",F39*$B$4) | L39: · 초콜릿 (기몀리, 리스)
B40: 19:00 ~ 20:00 | C40: Total Wine (Burbank) | D40: 🍷 술 구경 | E40: 19:30~20:30 🍷 Total Wine & More (Burbank, 수만종 술 구경) | G40: =IF(F40="","",F40*$B$4) | L40: · 시리얼 (매투테이스 크런치)
B41: 20:00 ~ 21:00 | C41: → 호텔 | D41: 🚗 복귀 | E41: 20:30~21:00 🚗 호텔 복귀 / 휴식 | G41: =IF(F41="","",F41*$B$4) | L41: · 타이레놀 머그 컵
...
